Watching for file changes with StatReloader
HTTP GET / 200 [0.03, 112.148.239.218:49491]
HTTP GET /static/rest_framework/css/bootstrap.min.css 304 [0.00, 112.148.239.218:49491]
HTTP GET /static/rest_framework/css/bootstrap-tweaks.css 304 [0.00, 112.148.239.218:57464]
HTTP GET /static/rest_framework/css/prettify.css 304 [0.00, 112.148.239.218:63191]
HTTP GET /static/rest_framework/js/jquery-3.5.1.min.js 304 [0.00, 112.148.239.218:64810]
HTTP GET /static/rest_framework/css/default.css 304 [0.01, 112.148.239.218:62062]
HTTP GET /static/rest_framework/js/ajax-form.js 304 [0.01, 112.148.239.218:64509]
HTTP GET /static/rest_framework/js/bootstrap.min.js 304 [0.00, 112.148.239.218:57464]
HTTP GET /static/rest_framework/js/csrf.js 304 [0.01, 112.148.239.218:49491]
HTTP GET /static/rest_framework/js/prettify-min.js 304 [0.00, 112.148.239.218:63191]
HTTP GET /static/rest_framework/js/default.js 304 [0.00, 112.148.239.218:64810]
HTTP GET /static/rest_framework/img/grid.png 304 [0.00, 112.148.239.218:64810]
Not Found: /favicon.ico
HTTP GET /favicon.ico 404 [0.01, 112.148.239.218:64810]
HTTP GET /user/location/ 200 [0.03, 112.148.239.218:64810]
HTTP GET /users/ 200 [0.06, 112.148.239.218:64810]
HTTP GET /users/ 200 [0.04, 112.148.239.218:64810]
/home/ubuntu/projects/helper/lightup_restAPI/views.py changed, reloading.
<class 'lightup.models.UserInfo'>
<class 'lightup.models.UserLocation'>
<class 'lightup.models.Donation'>
<class 'lightup.models.DonationUser'>
<class 'lightup.models.BorrowState'>
Performing system checks...

System check identified no issues (0 silenced).
August 12, 2021 - 00:22:29
Django version 3.1.3, using settings 'lightup_project.settings'
Starting ASGI/Channels version 3.0.4 development server at http://0:8000/
Quit the server with CONTROL-C.
Watching for file changes with StatReloader
HTTP GET /users/ 200 [0.09, 112.148.239.218:58604]
HTTP GET / 200 [0.02, 74.120.14.37:51370]
HTTP GET / 200 [0.01, 74.120.14.37:37594]
HTTP GET / 200 [0.01, 209.17.96.162:46981]
HTTP GET / 200 [0.01, 162.142.125.196:59166]
HTTP GET / 200 [0.01, 162.142.125.196:57352]
HTTP GET / 200 [0.01, 162.142.125.37:39690]
HTTP GET / 200 [0.01, 162.142.125.37:33970]
HTTP GET / 200 [0.02, 221.146.36.98:53145]
HTTP GET /static/rest_framework/css/bootstrap.min.css 200 [0.01, 221.146.36.98:53145]
HTTP GET /static/rest_framework/css/bootstrap-tweaks.css 200 [0.00, 221.146.36.98:53146]
HTTP GET /static/rest_framework/css/prettify.css 200 [0.01, 221.146.36.98:53147]
HTTP GET /static/rest_framework/css/default.css 200 [0.01, 221.146.36.98:53148]
HTTP GET /static/rest_framework/js/jquery-3.5.1.min.js 200 [0.01, 221.146.36.98:53149]
HTTP GET /static/rest_framework/js/ajax-form.js 200 [0.01, 221.146.36.98:53150]
HTTP GET /static/rest_framework/js/csrf.js 200 [0.01, 221.146.36.98:53146]
HTTP GET /static/rest_framework/js/bootstrap.min.js 200 [0.00, 221.146.36.98:53147]
HTTP GET /static/rest_framework/js/prettify-min.js 200 [0.01, 221.146.36.98:53148]
HTTP GET /static/rest_framework/js/default.js 200 [0.00, 221.146.36.98:53150]
HTTP GET /static/rest_framework/img/grid.png 200 [0.00, 221.146.36.98:53145]
Not Found: /favicon.ico
HTTP GET /favicon.ico 404 [0.03, 221.146.36.98:53151]
HTTP GET / 200 [0.01, 184.105.139.68:41820]
HTTP GET / 200 [0.01, 112.148.239.218:63877]
HTTP GET /static/rest_framework/css/bootstrap.min.css 304 [0.00, 112.148.239.218:63877]
HTTP GET /static/rest_framework/css/bootstrap-tweaks.css 304 [0.00, 112.148.239.218:52888]
HTTP GET /static/rest_framework/css/prettify.css 304 [0.00, 112.148.239.218:58700]
HTTP GET /static/rest_framework/css/default.css 304 [0.00, 112.148.239.218:53305]
HTTP GET /static/rest_framework/js/jquery-3.5.1.min.js 304 [0.00, 112.148.239.218:56307]
HTTP GET /static/rest_framework/js/ajax-form.js 304 [0.00, 112.148.239.218:54629]
HTTP GET /static/rest_framework/js/csrf.js 304 [0.00, 112.148.239.218:63877]
HTTP GET /static/rest_framework/js/bootstrap.min.js 304 [0.00, 112.148.239.218:52888]
HTTP GET /static/rest_framework/js/prettify-min.js 304 [0.00, 112.148.239.218:58700]
HTTP GET /static/rest_framework/js/default.js 304 [0.00, 112.148.239.218:56307]
HTTP GET /static/rest_framework/img/grid.png 304 [0.00, 112.148.239.218:56307]
Not Found: /favicon.ico
HTTP GET /favicon.ico 404 [0.01, 112.148.239.218:56307]
HTTP GET /users/ 200 [0.06, 112.148.239.218:56307]
HTTP GET /users/ 200 [0.04, 112.148.239.218:61178]
Invalid HTTP_HOST header: 'example.com'. You may need to add 'example.com' to ALLOWED_HOSTS.
Bad Request: http://example.com/
HTTP GET http://example.com/ 400 [0.04, 205.185.124.192:44938]
Bad Request: /users/
HTTP POST /users/ 400 [0.02, 221.146.36.98:55716]
Bad Request: /users/
HTTP POST /users/ 400 [0.01, 221.146.36.98:55854]
HTTP POST /users/ 201 [0.19, 221.146.36.98:55854]
Bad Request: /users/
HTTP POST /users/ 400 [0.01, 221.146.36.98:55893]
Bad Request: /users/
HTTP POST /users/ 400 [0.01, 221.146.36.98:55893]
Bad Request: /users/
HTTP POST /users/ 400 [0.01, 221.146.36.98:55893]
HTTP POST /users/ 201 [0.18, 221.146.36.98:55893]
HTTP GET /users/ 200 [0.05, 112.148.239.218:53505]
HTTP GET /users/ 200 [0.05, 112.148.239.218:53505]
Internal Server Error: /users/
Traceback (most recent call last):
  File "/home/ubuntu/venvs/lightup/lib/python3.8/site-packages/django/db/backends/utils.py", line 84, in _execute
    return self.cursor.execute(sql, params)
  File "/home/ubuntu/venvs/lightup/lib/python3.8/site-packages/django/db/backends/sqlite3/base.py", line 413, in execute
    return Database.Cursor.execute(self, query, params)
sqlite3.IntegrityError: UNIQUE constraint failed: auth_user.username

The above exception was the direct cause of the following exception:

Traceback (most recent call last):
  File "/home/ubuntu/venvs/lightup/lib/python3.8/site-packages/asgiref/sync.py", line 482, in thread_handler
    raise exc_info[1]
  File "/home/ubuntu/venvs/lightup/lib/python3.8/site-packages/django/core/handlers/exception.py", line 38, in inner
    response = await get_response(request)
  File "/home/ubuntu/venvs/lightup/lib/python3.8/site-packages/django/core/handlers/base.py", line 231, in _get_response_async
    response = await wrapped_callback(request, *callback_args, **callback_kwargs)
  File "/home/ubuntu/venvs/lightup/lib/python3.8/site-packages/asgiref/sync.py", line 444, in __call__
    ret = await asyncio.wait_for(future, timeout=None)
  File "/usr/lib/python3.8/asyncio/tasks.py", line 455, in wait_for
    return await fut
  File "/usr/lib/python3.8/concurrent/futures/thread.py", line 57, in run
    result = self.fn(*self.args, **self.kwargs)
  File "/home/ubuntu/venvs/lightup/lib/python3.8/site-packages/asgiref/sync.py", line 486, in thread_handler
    return func(*args, **kwargs)
  File "/home/ubuntu/venvs/lightup/lib/python3.8/site-packages/django/views/decorators/csrf.py", line 54, in wrapped_view
    return view_func(*args, **kwargs)
  File "/home/ubuntu/venvs/lightup/lib/python3.8/site-packages/rest_framework/viewsets.py", line 125, in view
    return self.dispatch(request, *args, **kwargs)
  File "/home/ubuntu/venvs/lightup/lib/python3.8/site-packages/rest_framework/views.py", line 509, in dispatch
    response = self.handle_exception(exc)
  File "/home/ubuntu/venvs/lightup/lib/python3.8/site-packages/rest_framework/views.py", line 469, in handle_exception
    self.raise_uncaught_exception(exc)
  File "/home/ubuntu/venvs/lightup/lib/python3.8/site-packages/rest_framework/views.py", line 480, in raise_uncaught_exception
    raise exc
  File "/home/ubuntu/venvs/lightup/lib/python3.8/site-packages/rest_framework/views.py", line 506, in dispatch
    response = handler(request, *args, **kwargs)
  File "/home/ubuntu/venvs/lightup/lib/python3.8/site-packages/rest_framework/mixins.py", line 19, in create
    self.perform_create(serializer)
  File "/home/ubuntu/venvs/lightup/lib/python3.8/site-packages/rest_framework/mixins.py", line 24, in perform_create
    serializer.save()
  File "/home/ubuntu/venvs/lightup/lib/python3.8/site-packages/rest_framework/serializers.py", line 205, in save
    self.instance = self.create(validated_data)
  File "/home/ubuntu/projects/helper/lightup_restAPI/serializers.py", line 37, in create
    user = User.objects.create(
  File "/home/ubuntu/venvs/lightup/lib/python3.8/site-packages/django/db/models/manager.py", line 85, in manager_method
    return getattr(self.get_queryset(), name)(*args, **kwargs)
  File "/home/ubuntu/venvs/lightup/lib/python3.8/site-packages/django/db/models/query.py", line 447, in create
    obj.save(force_insert=True, using=self.db)
  File "/home/ubuntu/venvs/lightup/lib/python3.8/site-packages/django/contrib/auth/base_user.py", line 67, in save
    super().save(*args, **kwargs)
  File "/home/ubuntu/venvs/lightup/lib/python3.8/site-packages/django/db/models/base.py", line 753, in save
    self.save_base(using=using, force_insert=force_insert,
  File "/home/ubuntu/venvs/lightup/lib/python3.8/site-packages/django/db/models/base.py", line 790, in save_base
    updated = self._save_table(
  File "/home/ubuntu/venvs/lightup/lib/python3.8/site-packages/django/db/models/base.py", line 895, in _save_table
    results = self._do_insert(cls._base_manager, using, fields, returning_fields, raw)
  File "/home/ubuntu/venvs/lightup/lib/python3.8/site-packages/django/db/models/base.py", line 933, in _do_insert
    return manager._insert(
  File "/home/ubuntu/venvs/lightup/lib/python3.8/site-packages/django/db/models/manager.py", line 85, in manager_method
    return getattr(self.get_queryset(), name)(*args, **kwargs)
  File "/home/ubuntu/venvs/lightup/lib/python3.8/site-packages/django/db/models/query.py", line 1254, in _insert
    return query.get_compiler(using=using).execute_sql(returning_fields)
  File "/home/ubuntu/venvs/lightup/lib/python3.8/site-packages/django/db/models/sql/compiler.py", line 1397, in execute_sql
    cursor.execute(sql, params)
  File "/home/ubuntu/venvs/lightup/lib/python3.8/site-packages/django/db/backends/utils.py", line 98, in execute
    return super().execute(sql, params)
  File "/home/ubuntu/venvs/lightup/lib/python3.8/site-packages/django/db/backends/utils.py", line 66, in execute
    return self._execute_with_wrappers(sql, params, many=False, executor=self._execute)
  File "/home/ubuntu/venvs/lightup/lib/python3.8/site-packages/django/db/backends/utils.py", line 75, in _execute_with_wrappers
    return executor(sql, params, many, context)
  File "/home/ubuntu/venvs/lightup/lib/python3.8/site-packages/django/db/backends/utils.py", line 84, in _execute
    return self.cursor.execute(sql, params)
  File "/home/ubuntu/venvs/lightup/lib/python3.8/site-packages/django/db/utils.py", line 90, in __exit__
    raise dj_exc_value.with_traceback(traceback) from exc_value
  File "/home/ubuntu/venvs/lightup/lib/python3.8/site-packages/django/db/backends/utils.py", line 84, in _execute
    return self.cursor.execute(sql, params)
  File "/home/ubuntu/venvs/lightup/lib/python3.8/site-packages/django/db/backends/sqlite3/base.py", line 413, in execute
    return Database.Cursor.execute(self, query, params)
django.db.utils.IntegrityError: UNIQUE constraint failed: auth_user.username
HTTP POST /users/ 500 [0.09, 221.146.36.98:56108]
Bad Request: /users/
HTTP POST /users/ 400 [0.01, 221.146.36.98:56108]
HTTP GET / 200 [0.01, 221.146.36.98:56370]
HTTP GET /static/rest_framework/css/bootstrap-tweaks.css 200 [0.00, 221.146.36.98:60542]
HTTP GET /static/rest_framework/css/bootstrap.min.css 200 [0.00, 221.146.36.98:56370]
HTTP GET /static/rest_framework/js/jquery-3.5.1.min.js 200 [0.00, 221.146.36.98:62818]
HTTP GET /static/rest_framework/css/default.css 200 [0.01, 221.146.36.98:49204]
HTTP GET /static/rest_framework/css/prettify.css 200 [0.01, 221.146.36.98:65433]
HTTP GET /static/rest_framework/js/ajax-form.js 200 [0.01, 221.146.36.98:60542]
HTTP GET /static/rest_framework/js/csrf.js 200 [0.01, 221.146.36.98:65272]
HTTP GET /static/rest_framework/js/bootstrap.min.js 200 [0.00, 221.146.36.98:49204]
HTTP GET /static/rest_framework/js/prettify-min.js 200 [0.00, 221.146.36.98:65433]
HTTP GET /static/rest_framework/js/default.js 200 [0.00, 221.146.36.98:65272]
HTTP GET /static/rest_framework/img/grid.png 200 [0.00, 221.146.36.98:65272]
Not Found: /favicon.ico
HTTP GET /favicon.ico 404 [0.01, 221.146.36.98:65272]
HTTP GET /user/location/ 200 [0.03, 221.146.36.98:65272]
HTTP GET / 200 [0.01, 221.146.36.98:55459]
HTTP GET /users/ 200 [0.05, 221.146.36.98:55459]
HTTP GET /user/location/ 200 [0.02, 221.146.36.98:55459]
Internal Server Error: /users/
Traceback (most recent call last):
  File "/home/ubuntu/venvs/lightup/lib/python3.8/site-packages/django/db/backends/utils.py", line 84, in _execute
    return self.cursor.execute(sql, params)
  File "/home/ubuntu/venvs/lightup/lib/python3.8/site-packages/django/db/backends/sqlite3/base.py", line 413, in execute
    return Database.Cursor.execute(self, query, params)
sqlite3.IntegrityError: UNIQUE constraint failed: auth_user.username

The above exception was the direct cause of the following exception:

Traceback (most recent call last):
  File "/home/ubuntu/venvs/lightup/lib/python3.8/site-packages/asgiref/sync.py", line 482, in thread_handler
    raise exc_info[1]
  File "/home/ubuntu/venvs/lightup/lib/python3.8/site-packages/django/core/handlers/exception.py", line 38, in inner
    response = await get_response(request)
  File "/home/ubuntu/venvs/lightup/lib/python3.8/site-packages/django/core/handlers/base.py", line 231, in _get_response_async
    response = await wrapped_callback(request, *callback_args, **callback_kwargs)
  File "/home/ubuntu/venvs/lightup/lib/python3.8/site-packages/asgiref/sync.py", line 444, in __call__
    ret = await asyncio.wait_for(future, timeout=None)
  File "/usr/lib/python3.8/asyncio/tasks.py", line 455, in wait_for
    return await fut
  File "/usr/lib/python3.8/concurrent/futures/thread.py", line 57, in run
    result = self.fn(*self.args, **self.kwargs)
  File "/home/ubuntu/venvs/lightup/lib/python3.8/site-packages/asgiref/sync.py", line 486, in thread_handler
    return func(*args, **kwargs)
  File "/home/ubuntu/venvs/lightup/lib/python3.8/site-packages/django/views/decorators/csrf.py", line 54, in wrapped_view
    return view_func(*args, **kwargs)
  File "/home/ubuntu/venvs/lightup/lib/python3.8/site-packages/rest_framework/viewsets.py", line 125, in view
    return self.dispatch(request, *args, **kwargs)
  File "/home/ubuntu/venvs/lightup/lib/python3.8/site-packages/rest_framework/views.py", line 509, in dispatch
    response = self.handle_exception(exc)
  File "/home/ubuntu/venvs/lightup/lib/python3.8/site-packages/rest_framework/views.py", line 469, in handle_exception
    self.raise_uncaught_exception(exc)
  File "/home/ubuntu/venvs/lightup/lib/python3.8/site-packages/rest_framework/views.py", line 480, in raise_uncaught_exception
    raise exc
  File "/home/ubuntu/venvs/lightup/lib/python3.8/site-packages/rest_framework/views.py", line 506, in dispatch
    response = handler(request, *args, **kwargs)
  File "/home/ubuntu/venvs/lightup/lib/python3.8/site-packages/rest_framework/mixins.py", line 19, in create
    self.perform_create(serializer)
  File "/home/ubuntu/venvs/lightup/lib/python3.8/site-packages/rest_framework/mixins.py", line 24, in perform_create
    serializer.save()
  File "/home/ubuntu/venvs/lightup/lib/python3.8/site-packages/rest_framework/serializers.py", line 205, in save
    self.instance = self.create(validated_data)
  File "/home/ubuntu/projects/helper/lightup_restAPI/serializers.py", line 37, in create
    user = User.objects.create(
  File "/home/ubuntu/venvs/lightup/lib/python3.8/site-packages/django/db/models/manager.py", line 85, in manager_method
    return getattr(self.get_queryset(), name)(*args, **kwargs)
  File "/home/ubuntu/venvs/lightup/lib/python3.8/site-packages/django/db/models/query.py", line 447, in create
    obj.save(force_insert=True, using=self.db)
  File "/home/ubuntu/venvs/lightup/lib/python3.8/site-packages/django/contrib/auth/base_user.py", line 67, in save
    super().save(*args, **kwargs)
  File "/home/ubuntu/venvs/lightup/lib/python3.8/site-packages/django/db/models/base.py", line 753, in save
    self.save_base(using=using, force_insert=force_insert,
  File "/home/ubuntu/venvs/lightup/lib/python3.8/site-packages/django/db/models/base.py", line 790, in save_base
    updated = self._save_table(
  File "/home/ubuntu/venvs/lightup/lib/python3.8/site-packages/django/db/models/base.py", line 895, in _save_table
    results = self._do_insert(cls._base_manager, using, fields, returning_fields, raw)
  File "/home/ubuntu/venvs/lightup/lib/python3.8/site-packages/django/db/models/base.py", line 933, in _do_insert
    return manager._insert(
  File "/home/ubuntu/venvs/lightup/lib/python3.8/site-packages/django/db/models/manager.py", line 85, in manager_method
    return getattr(self.get_queryset(), name)(*args, **kwargs)
  File "/home/ubuntu/venvs/lightup/lib/python3.8/site-packages/django/db/models/query.py", line 1254, in _insert
    return query.get_compiler(using=using).execute_sql(returning_fields)
  File "/home/ubuntu/venvs/lightup/lib/python3.8/site-packages/django/db/models/sql/compiler.py", line 1397, in execute_sql
    cursor.execute(sql, params)
  File "/home/ubuntu/venvs/lightup/lib/python3.8/site-packages/django/db/backends/utils.py", line 98, in execute
    return super().execute(sql, params)
  File "/home/ubuntu/venvs/lightup/lib/python3.8/site-packages/django/db/backends/utils.py", line 66, in execute
    return self._execute_with_wrappers(sql, params, many=False, executor=self._execute)
  File "/home/ubuntu/venvs/lightup/lib/python3.8/site-packages/django/db/backends/utils.py", line 75, in _execute_with_wrappers
    return executor(sql, params, many, context)
  File "/home/ubuntu/venvs/lightup/lib/python3.8/site-packages/django/db/backends/utils.py", line 84, in _execute
    return self.cursor.execute(sql, params)
  File "/home/ubuntu/venvs/lightup/lib/python3.8/site-packages/django/db/utils.py", line 90, in __exit__
    raise dj_exc_value.with_traceback(traceback) from exc_value
  File "/home/ubuntu/venvs/lightup/lib/python3.8/site-packages/django/db/backends/utils.py", line 84, in _execute
    return self.cursor.execute(sql, params)
  File "/home/ubuntu/venvs/lightup/lib/python3.8/site-packages/django/db/backends/sqlite3/base.py", line 413, in execute
    return Database.Cursor.execute(self, query, params)
django.db.utils.IntegrityError: UNIQUE constraint failed: auth_user.username
HTTP POST /users/ 500 [0.07, 221.146.36.98:56291]
HTTP GET / 200 [0.01, 221.146.36.98:56310]
HTTP GET /users/ 200 [0.05, 221.146.36.98:56310]
HTTP POST /users/ 201 [0.18, 221.146.36.98:56321]
HTTP GET /users/ 200 [0.05, 221.146.36.98:56310]
Bad Request: /users/
HTTP POST /users/ 400 [0.01, 221.146.36.98:56418]
HTTP POST /users/ 201 [0.18, 221.146.36.98:56418]
HTTP GET /users/ 200 [0.05, 221.146.36.98:50605]
Bad Request: /users/
HTTP POST /users/ 400 [0.01, 221.146.36.98:56485]
HTTP POST /users/ 201 [0.18, 221.146.36.98:56485]
Bad Request: /users/
HTTP POST /users/ 400 [0.01, 221.146.36.98:56620]
Bad Request: /users/
HTTP POST /users/ 400 [0.01, 221.146.36.98:56620]
Bad Request: /users/
HTTP POST /users/ 400 [0.01, 221.146.36.98:57561]
Bad Request: /users/
HTTP POST /users/ 400 [0.01, 221.146.36.98:57561]
Bad Request: /users/
HTTP POST /users/ 400 [0.01, 221.146.36.98:57561]
Bad Request: /users/
HTTP POST /users/ 400 [0.01, 221.146.36.98:57561]
HTTP POST /users/ 201 [0.18, 221.146.36.98:57561]
HTTP POST /login/ 200 [0.16, 221.146.36.98:57888]
HTTP POST /login/ 200 [0.16, 221.146.36.98:57888]
Internal Server Error: /users/
Traceback (most recent call last):
  File "/home/ubuntu/venvs/lightup/lib/python3.8/site-packages/django/db/backends/utils.py", line 84, in _execute
    return self.cursor.execute(sql, params)
  File "/home/ubuntu/venvs/lightup/lib/python3.8/site-packages/django/db/backends/sqlite3/base.py", line 413, in execute
    return Database.Cursor.execute(self, query, params)
sqlite3.IntegrityError: UNIQUE constraint failed: auth_user.username

The above exception was the direct cause of the following exception:

Traceback (most recent call last):
  File "/home/ubuntu/venvs/lightup/lib/python3.8/site-packages/asgiref/sync.py", line 482, in thread_handler
    raise exc_info[1]
  File "/home/ubuntu/venvs/lightup/lib/python3.8/site-packages/django/core/handlers/exception.py", line 38, in inner
    response = await get_response(request)
  File "/home/ubuntu/venvs/lightup/lib/python3.8/site-packages/django/core/handlers/base.py", line 231, in _get_response_async
    response = await wrapped_callback(request, *callback_args, **callback_kwargs)
  File "/home/ubuntu/venvs/lightup/lib/python3.8/site-packages/asgiref/sync.py", line 444, in __call__
    ret = await asyncio.wait_for(future, timeout=None)
  File "/usr/lib/python3.8/asyncio/tasks.py", line 455, in wait_for
    return await fut
  File "/usr/lib/python3.8/concurrent/futures/thread.py", line 57, in run
    result = self.fn(*self.args, **self.kwargs)
  File "/home/ubuntu/venvs/lightup/lib/python3.8/site-packages/asgiref/sync.py", line 486, in thread_handler
    return func(*args, **kwargs)
  File "/home/ubuntu/venvs/lightup/lib/python3.8/site-packages/django/views/decorators/csrf.py", line 54, in wrapped_view
    return view_func(*args, **kwargs)
  File "/home/ubuntu/venvs/lightup/lib/python3.8/site-packages/rest_framework/viewsets.py", line 125, in view
    return self.dispatch(request, *args, **kwargs)
  File "/home/ubuntu/venvs/lightup/lib/python3.8/site-packages/rest_framework/views.py", line 509, in dispatch
    response = self.handle_exception(exc)
  File "/home/ubuntu/venvs/lightup/lib/python3.8/site-packages/rest_framework/views.py", line 469, in handle_exception
    self.raise_uncaught_exception(exc)
  File "/home/ubuntu/venvs/lightup/lib/python3.8/site-packages/rest_framework/views.py", line 480, in raise_uncaught_exception
    raise exc
  File "/home/ubuntu/venvs/lightup/lib/python3.8/site-packages/rest_framework/views.py", line 506, in dispatch
    response = handler(request, *args, **kwargs)
  File "/home/ubuntu/venvs/lightup/lib/python3.8/site-packages/rest_framework/mixins.py", line 19, in create
    self.perform_create(serializer)
  File "/home/ubuntu/venvs/lightup/lib/python3.8/site-packages/rest_framework/mixins.py", line 24, in perform_create
    serializer.save()
  File "/home/ubuntu/venvs/lightup/lib/python3.8/site-packages/rest_framework/serializers.py", line 205, in save
    self.instance = self.create(validated_data)
  File "/home/ubuntu/projects/helper/lightup_restAPI/serializers.py", line 37, in create
    user = User.objects.create(
  File "/home/ubuntu/venvs/lightup/lib/python3.8/site-packages/django/db/models/manager.py", line 85, in manager_method
    return getattr(self.get_queryset(), name)(*args, **kwargs)
  File "/home/ubuntu/venvs/lightup/lib/python3.8/site-packages/django/db/models/query.py", line 447, in create
    obj.save(force_insert=True, using=self.db)
  File "/home/ubuntu/venvs/lightup/lib/python3.8/site-packages/django/contrib/auth/base_user.py", line 67, in save
    super().save(*args, **kwargs)
  File "/home/ubuntu/venvs/lightup/lib/python3.8/site-packages/django/db/models/base.py", line 753, in save
    self.save_base(using=using, force_insert=force_insert,
  File "/home/ubuntu/venvs/lightup/lib/python3.8/site-packages/django/db/models/base.py", line 790, in save_base
    updated = self._save_table(
  File "/home/ubuntu/venvs/lightup/lib/python3.8/site-packages/django/db/models/base.py", line 895, in _save_table
    results = self._do_insert(cls._base_manager, using, fields, returning_fields, raw)
  File "/home/ubuntu/venvs/lightup/lib/python3.8/site-packages/django/db/models/base.py", line 933, in _do_insert
    return manager._insert(
  File "/home/ubuntu/venvs/lightup/lib/python3.8/site-packages/django/db/models/manager.py", line 85, in manager_method
    return getattr(self.get_queryset(), name)(*args, **kwargs)
  File "/home/ubuntu/venvs/lightup/lib/python3.8/site-packages/django/db/models/query.py", line 1254, in _insert
    return query.get_compiler(using=using).execute_sql(returning_fields)
  File "/home/ubuntu/venvs/lightup/lib/python3.8/site-packages/django/db/models/sql/compiler.py", line 1397, in execute_sql
    cursor.execute(sql, params)
  File "/home/ubuntu/venvs/lightup/lib/python3.8/site-packages/django/db/backends/utils.py", line 98, in execute
    return super().execute(sql, params)
  File "/home/ubuntu/venvs/lightup/lib/python3.8/site-packages/django/db/backends/utils.py", line 66, in execute
    return self._execute_with_wrappers(sql, params, many=False, executor=self._execute)
  File "/home/ubuntu/venvs/lightup/lib/python3.8/site-packages/django/db/backends/utils.py", line 75, in _execute_with_wrappers
    return executor(sql, params, many, context)
  File "/home/ubuntu/venvs/lightup/lib/python3.8/site-packages/django/db/backends/utils.py", line 84, in _execute
    return self.cursor.execute(sql, params)
  File "/home/ubuntu/venvs/lightup/lib/python3.8/site-packages/django/db/utils.py", line 90, in __exit__
    raise dj_exc_value.with_traceback(traceback) from exc_value
  File "/home/ubuntu/venvs/lightup/lib/python3.8/site-packages/django/db/backends/utils.py", line 84, in _execute
    return self.cursor.execute(sql, params)
  File "/home/ubuntu/venvs/lightup/lib/python3.8/site-packages/django/db/backends/sqlite3/base.py", line 413, in execute
    return Database.Cursor.execute(self, query, params)
django.db.utils.IntegrityError: UNIQUE constraint failed: auth_user.username
HTTP POST /users/ 500 [0.10, 221.146.36.98:57931]
HTTP GET / 200 [0.02, 221.146.36.98:57956]
HTTP GET /static/rest_framework/css/bootstrap.min.css 304 [0.00, 221.146.36.98:57961]
HTTP GET /static/rest_framework/css/prettify.css 304 [0.00, 221.146.36.98:57960]
HTTP GET /static/rest_framework/js/ajax-form.js 304 [0.01, 221.146.36.98:57959]
HTTP GET /static/rest_framework/css/bootstrap-tweaks.css 304 [0.01, 221.146.36.98:57958]
HTTP GET /static/rest_framework/css/default.css 304 [0.01, 221.146.36.98:57957]
HTTP GET /static/rest_framework/js/jquery-3.5.1.min.js 304 [0.01, 221.146.36.98:57956]
HTTP GET /static/rest_framework/js/csrf.js 304 [0.00, 221.146.36.98:57961]
HTTP GET /static/rest_framework/js/bootstrap.min.js 304 [0.00, 221.146.36.98:57960]
HTTP GET /static/rest_framework/js/prettify-min.js 304 [0.00, 221.146.36.98:57959]
HTTP GET /static/rest_framework/js/default.js 304 [0.00, 221.146.36.98:57958]
HTTP GET /static/rest_framework/img/grid.png 304 [0.00, 221.146.36.98:57957]
HTTP GET / 200 [0.01, 221.146.36.98:57956]
HTTP GET /static/rest_framework/css/bootstrap-tweaks.css 200 [0.00, 221.146.36.98:57960]
HTTP GET /static/rest_framework/css/bootstrap.min.css 200 [0.01, 221.146.36.98:57958]
HTTP GET /static/rest_framework/css/default.css 200 [0.01, 221.146.36.98:57956]
HTTP GET /static/rest_framework/css/prettify.css 200 [0.01, 221.146.36.98:57957]
HTTP GET /static/rest_framework/js/ajax-form.js 200 [0.01, 221.146.36.98:57961]
HTTP GET /static/rest_framework/js/jquery-3.5.1.min.js 200 [0.01, 221.146.36.98:57959]
HTTP GET /static/rest_framework/js/csrf.js 200 [0.01, 221.146.36.98:57960]
HTTP GET /static/rest_framework/js/bootstrap.min.js 200 [0.00, 221.146.36.98:57956]
HTTP GET /static/rest_framework/js/prettify-min.js 200 [0.00, 221.146.36.98:57957]
HTTP GET /static/rest_framework/js/default.js 200 [0.00, 221.146.36.98:57961]
HTTP GET /static/rest_framework/img/grid.png 200 [0.00, 221.146.36.98:57960]
HTTP GET /users/ 200 [0.07, 221.146.36.98:57956]
Not Found: /favicon.ico
HTTP GET /favicon.ico 404 [0.01, 221.146.36.98:57966]
HTTP GET /users/ 200 [0.06, 221.146.36.98:57956]
Internal Server Error: /users/
Traceback (most recent call last):
  File "/home/ubuntu/venvs/lightup/lib/python3.8/site-packages/django/db/backends/utils.py", line 84, in _execute
    return self.cursor.execute(sql, params)
  File "/home/ubuntu/venvs/lightup/lib/python3.8/site-packages/django/db/backends/sqlite3/base.py", line 413, in execute
    return Database.Cursor.execute(self, query, params)
sqlite3.IntegrityError: UNIQUE constraint failed: auth_user.username

The above exception was the direct cause of the following exception:

Traceback (most recent call last):
  File "/home/ubuntu/venvs/lightup/lib/python3.8/site-packages/asgiref/sync.py", line 482, in thread_handler
    raise exc_info[1]
  File "/home/ubuntu/venvs/lightup/lib/python3.8/site-packages/django/core/handlers/exception.py", line 38, in inner
    response = await get_response(request)
  File "/home/ubuntu/venvs/lightup/lib/python3.8/site-packages/django/core/handlers/base.py", line 231, in _get_response_async
    response = await wrapped_callback(request, *callback_args, **callback_kwargs)
  File "/home/ubuntu/venvs/lightup/lib/python3.8/site-packages/asgiref/sync.py", line 444, in __call__
    ret = await asyncio.wait_for(future, timeout=None)
  File "/usr/lib/python3.8/asyncio/tasks.py", line 455, in wait_for
    return await fut
  File "/usr/lib/python3.8/concurrent/futures/thread.py", line 57, in run
    result = self.fn(*self.args, **self.kwargs)
  File "/home/ubuntu/venvs/lightup/lib/python3.8/site-packages/asgiref/sync.py", line 486, in thread_handler
    return func(*args, **kwargs)
  File "/home/ubuntu/venvs/lightup/lib/python3.8/site-packages/django/views/decorators/csrf.py", line 54, in wrapped_view
    return view_func(*args, **kwargs)
  File "/home/ubuntu/venvs/lightup/lib/python3.8/site-packages/rest_framework/viewsets.py", line 125, in view
    return self.dispatch(request, *args, **kwargs)
  File "/home/ubuntu/venvs/lightup/lib/python3.8/site-packages/rest_framework/views.py", line 509, in dispatch
    response = self.handle_exception(exc)
  File "/home/ubuntu/venvs/lightup/lib/python3.8/site-packages/rest_framework/views.py", line 469, in handle_exception
    self.raise_uncaught_exception(exc)
  File "/home/ubuntu/venvs/lightup/lib/python3.8/site-packages/rest_framework/views.py", line 480, in raise_uncaught_exception
    raise exc
  File "/home/ubuntu/venvs/lightup/lib/python3.8/site-packages/rest_framework/views.py", line 506, in dispatch
    response = handler(request, *args, **kwargs)
  File "/home/ubuntu/venvs/lightup/lib/python3.8/site-packages/rest_framework/mixins.py", line 19, in create
    self.perform_create(serializer)
  File "/home/ubuntu/venvs/lightup/lib/python3.8/site-packages/rest_framework/mixins.py", line 24, in perform_create
    serializer.save()
  File "/home/ubuntu/venvs/lightup/lib/python3.8/site-packages/rest_framework/serializers.py", line 205, in save
    self.instance = self.create(validated_data)
  File "/home/ubuntu/projects/helper/lightup_restAPI/serializers.py", line 37, in create
    user = User.objects.create(
  File "/home/ubuntu/venvs/lightup/lib/python3.8/site-packages/django/db/models/manager.py", line 85, in manager_method
    return getattr(self.get_queryset(), name)(*args, **kwargs)
  File "/home/ubuntu/venvs/lightup/lib/python3.8/site-packages/django/db/models/query.py", line 447, in create
    obj.save(force_insert=True, using=self.db)
  File "/home/ubuntu/venvs/lightup/lib/python3.8/site-packages/django/contrib/auth/base_user.py", line 67, in save
    super().save(*args, **kwargs)
  File "/home/ubuntu/venvs/lightup/lib/python3.8/site-packages/django/db/models/base.py", line 753, in save
    self.save_base(using=using, force_insert=force_insert,
  File "/home/ubuntu/venvs/lightup/lib/python3.8/site-packages/django/db/models/base.py", line 790, in save_base
    updated = self._save_table(
  File "/home/ubuntu/venvs/lightup/lib/python3.8/site-packages/django/db/models/base.py", line 895, in _save_table
    results = self._do_insert(cls._base_manager, using, fields, returning_fields, raw)
  File "/home/ubuntu/venvs/lightup/lib/python3.8/site-packages/django/db/models/base.py", line 933, in _do_insert
    return manager._insert(
  File "/home/ubuntu/venvs/lightup/lib/python3.8/site-packages/django/db/models/manager.py", line 85, in manager_method
    return getattr(self.get_queryset(), name)(*args, **kwargs)
  File "/home/ubuntu/venvs/lightup/lib/python3.8/site-packages/django/db/models/query.py", line 1254, in _insert
    return query.get_compiler(using=using).execute_sql(returning_fields)
  File "/home/ubuntu/venvs/lightup/lib/python3.8/site-packages/django/db/models/sql/compiler.py", line 1397, in execute_sql
    cursor.execute(sql, params)
  File "/home/ubuntu/venvs/lightup/lib/python3.8/site-packages/django/db/backends/utils.py", line 98, in execute
    return super().execute(sql, params)
  File "/home/ubuntu/venvs/lightup/lib/python3.8/site-packages/django/db/backends/utils.py", line 66, in execute
    return self._execute_with_wrappers(sql, params, many=False, executor=self._execute)
  File "/home/ubuntu/venvs/lightup/lib/python3.8/site-packages/django/db/backends/utils.py", line 75, in _execute_with_wrappers
    return executor(sql, params, many, context)
  File "/home/ubuntu/venvs/lightup/lib/python3.8/site-packages/django/db/backends/utils.py", line 84, in _execute
    return self.cursor.execute(sql, params)
  File "/home/ubuntu/venvs/lightup/lib/python3.8/site-packages/django/db/utils.py", line 90, in __exit__
    raise dj_exc_value.with_traceback(traceback) from exc_value
  File "/home/ubuntu/venvs/lightup/lib/python3.8/site-packages/django/db/backends/utils.py", line 84, in _execute
    return self.cursor.execute(sql, params)
  File "/home/ubuntu/venvs/lightup/lib/python3.8/site-packages/django/db/backends/sqlite3/base.py", line 413, in execute
    return Database.Cursor.execute(self, query, params)
django.db.utils.IntegrityError: UNIQUE constraint failed: auth_user.username
HTTP POST /users/ 500 [0.07, 221.146.36.98:57978]
Internal Server Error: /users/
Traceback (most recent call last):
  File "/home/ubuntu/venvs/lightup/lib/python3.8/site-packages/django/db/backends/utils.py", line 84, in _execute
    return self.cursor.execute(sql, params)
  File "/home/ubuntu/venvs/lightup/lib/python3.8/site-packages/django/db/backends/sqlite3/base.py", line 413, in execute
    return Database.Cursor.execute(self, query, params)
sqlite3.IntegrityError: UNIQUE constraint failed: auth_user.username

The above exception was the direct cause of the following exception:

Traceback (most recent call last):
  File "/home/ubuntu/venvs/lightup/lib/python3.8/site-packages/asgiref/sync.py", line 482, in thread_handler
    raise exc_info[1]
  File "/home/ubuntu/venvs/lightup/lib/python3.8/site-packages/django/core/handlers/exception.py", line 38, in inner
    response = await get_response(request)
  File "/home/ubuntu/venvs/lightup/lib/python3.8/site-packages/django/core/handlers/base.py", line 231, in _get_response_async
    response = await wrapped_callback(request, *callback_args, **callback_kwargs)
  File "/home/ubuntu/venvs/lightup/lib/python3.8/site-packages/asgiref/sync.py", line 444, in __call__
    ret = await asyncio.wait_for(future, timeout=None)
  File "/usr/lib/python3.8/asyncio/tasks.py", line 455, in wait_for
    return await fut
  File "/usr/lib/python3.8/concurrent/futures/thread.py", line 57, in run
    result = self.fn(*self.args, **self.kwargs)
  File "/home/ubuntu/venvs/lightup/lib/python3.8/site-packages/asgiref/sync.py", line 486, in thread_handler
    return func(*args, **kwargs)
  File "/home/ubuntu/venvs/lightup/lib/python3.8/site-packages/django/views/decorators/csrf.py", line 54, in wrapped_view
    return view_func(*args, **kwargs)
  File "/home/ubuntu/venvs/lightup/lib/python3.8/site-packages/rest_framework/viewsets.py", line 125, in view
    return self.dispatch(request, *args, **kwargs)
  File "/home/ubuntu/venvs/lightup/lib/python3.8/site-packages/rest_framework/views.py", line 509, in dispatch
    response = self.handle_exception(exc)
  File "/home/ubuntu/venvs/lightup/lib/python3.8/site-packages/rest_framework/views.py", line 469, in handle_exception
    self.raise_uncaught_exception(exc)
  File "/home/ubuntu/venvs/lightup/lib/python3.8/site-packages/rest_framework/views.py", line 480, in raise_uncaught_exception
    raise exc
  File "/home/ubuntu/venvs/lightup/lib/python3.8/site-packages/rest_framework/views.py", line 506, in dispatch
    response = handler(request, *args, **kwargs)
  File "/home/ubuntu/venvs/lightup/lib/python3.8/site-packages/rest_framework/mixins.py", line 19, in create
    self.perform_create(serializer)
  File "/home/ubuntu/venvs/lightup/lib/python3.8/site-packages/rest_framework/mixins.py", line 24, in perform_create
    serializer.save()
  File "/home/ubuntu/venvs/lightup/lib/python3.8/site-packages/rest_framework/serializers.py", line 205, in save
    self.instance = self.create(validated_data)
  File "/home/ubuntu/projects/helper/lightup_restAPI/serializers.py", line 37, in create
    user = User.objects.create(
  File "/home/ubuntu/venvs/lightup/lib/python3.8/site-packages/django/db/models/manager.py", line 85, in manager_method
    return getattr(self.get_queryset(), name)(*args, **kwargs)
  File "/home/ubuntu/venvs/lightup/lib/python3.8/site-packages/django/db/models/query.py", line 447, in create
    obj.save(force_insert=True, using=self.db)
  File "/home/ubuntu/venvs/lightup/lib/python3.8/site-packages/django/contrib/auth/base_user.py", line 67, in save
    super().save(*args, **kwargs)
  File "/home/ubuntu/venvs/lightup/lib/python3.8/site-packages/django/db/models/base.py", line 753, in save
    self.save_base(using=using, force_insert=force_insert,
  File "/home/ubuntu/venvs/lightup/lib/python3.8/site-packages/django/db/models/base.py", line 790, in save_base
    updated = self._save_table(
  File "/home/ubuntu/venvs/lightup/lib/python3.8/site-packages/django/db/models/base.py", line 895, in _save_table
    results = self._do_insert(cls._base_manager, using, fields, returning_fields, raw)
  File "/home/ubuntu/venvs/lightup/lib/python3.8/site-packages/django/db/models/base.py", line 933, in _do_insert
    return manager._insert(
  File "/home/ubuntu/venvs/lightup/lib/python3.8/site-packages/django/db/models/manager.py", line 85, in manager_method
    return getattr(self.get_queryset(), name)(*args, **kwargs)
  File "/home/ubuntu/venvs/lightup/lib/python3.8/site-packages/django/db/models/query.py", line 1254, in _insert
    return query.get_compiler(using=using).execute_sql(returning_fields)
  File "/home/ubuntu/venvs/lightup/lib/python3.8/site-packages/django/db/models/sql/compiler.py", line 1397, in execute_sql
    cursor.execute(sql, params)
  File "/home/ubuntu/venvs/lightup/lib/python3.8/site-packages/django/db/backends/utils.py", line 98, in execute
    return super().execute(sql, params)
  File "/home/ubuntu/venvs/lightup/lib/python3.8/site-packages/django/db/backends/utils.py", line 66, in execute
    return self._execute_with_wrappers(sql, params, many=False, executor=self._execute)
  File "/home/ubuntu/venvs/lightup/lib/python3.8/site-packages/django/db/backends/utils.py", line 75, in _execute_with_wrappers
    return executor(sql, params, many, context)
  File "/home/ubuntu/venvs/lightup/lib/python3.8/site-packages/django/db/backends/utils.py", line 84, in _execute
    return self.cursor.execute(sql, params)
  File "/home/ubuntu/venvs/lightup/lib/python3.8/site-packages/django/db/utils.py", line 90, in __exit__
    raise dj_exc_value.with_traceback(traceback) from exc_value
  File "/home/ubuntu/venvs/lightup/lib/python3.8/site-packages/django/db/backends/utils.py", line 84, in _execute
    return self.cursor.execute(sql, params)
  File "/home/ubuntu/venvs/lightup/lib/python3.8/site-packages/django/db/backends/sqlite3/base.py", line 413, in execute
    return Database.Cursor.execute(self, query, params)
django.db.utils.IntegrityError: UNIQUE constraint failed: auth_user.username
HTTP POST /users/ 500 [0.07, 221.146.36.98:57978]
Internal Server Error: /users/
Traceback (most recent call last):
  File "/home/ubuntu/venvs/lightup/lib/python3.8/site-packages/django/db/backends/utils.py", line 84, in _execute
    return self.cursor.execute(sql, params)
  File "/home/ubuntu/venvs/lightup/lib/python3.8/site-packages/django/db/backends/sqlite3/base.py", line 413, in execute
    return Database.Cursor.execute(self, query, params)
sqlite3.IntegrityError: UNIQUE constraint failed: auth_user.username

The above exception was the direct cause of the following exception:

Traceback (most recent call last):
  File "/home/ubuntu/venvs/lightup/lib/python3.8/site-packages/asgiref/sync.py", line 482, in thread_handler
    raise exc_info[1]
  File "/home/ubuntu/venvs/lightup/lib/python3.8/site-packages/django/core/handlers/exception.py", line 38, in inner
    response = await get_response(request)
  File "/home/ubuntu/venvs/lightup/lib/python3.8/site-packages/django/core/handlers/base.py", line 231, in _get_response_async
    response = await wrapped_callback(request, *callback_args, **callback_kwargs)
  File "/home/ubuntu/venvs/lightup/lib/python3.8/site-packages/asgiref/sync.py", line 444, in __call__
    ret = await asyncio.wait_for(future, timeout=None)
  File "/usr/lib/python3.8/asyncio/tasks.py", line 455, in wait_for
    return await fut
  File "/usr/lib/python3.8/concurrent/futures/thread.py", line 57, in run
    result = self.fn(*self.args, **self.kwargs)
  File "/home/ubuntu/venvs/lightup/lib/python3.8/site-packages/asgiref/sync.py", line 486, in thread_handler
    return func(*args, **kwargs)
  File "/home/ubuntu/venvs/lightup/lib/python3.8/site-packages/django/views/decorators/csrf.py", line 54, in wrapped_view
    return view_func(*args, **kwargs)
  File "/home/ubuntu/venvs/lightup/lib/python3.8/site-packages/rest_framework/viewsets.py", line 125, in view
    return self.dispatch(request, *args, **kwargs)
  File "/home/ubuntu/venvs/lightup/lib/python3.8/site-packages/rest_framework/views.py", line 509, in dispatch
    response = self.handle_exception(exc)
  File "/home/ubuntu/venvs/lightup/lib/python3.8/site-packages/rest_framework/views.py", line 469, in handle_exception
    self.raise_uncaught_exception(exc)
  File "/home/ubuntu/venvs/lightup/lib/python3.8/site-packages/rest_framework/views.py", line 480, in raise_uncaught_exception
    raise exc
  File "/home/ubuntu/venvs/lightup/lib/python3.8/site-packages/rest_framework/views.py", line 506, in dispatch
    response = handler(request, *args, **kwargs)
  File "/home/ubuntu/venvs/lightup/lib/python3.8/site-packages/rest_framework/mixins.py", line 19, in create
    self.perform_create(serializer)
  File "/home/ubuntu/venvs/lightup/lib/python3.8/site-packages/rest_framework/mixins.py", line 24, in perform_create
    serializer.save()
  File "/home/ubuntu/venvs/lightup/lib/python3.8/site-packages/rest_framework/serializers.py", line 205, in save
    self.instance = self.create(validated_data)
  File "/home/ubuntu/projects/helper/lightup_restAPI/serializers.py", line 37, in create
    user = User.objects.create(
  File "/home/ubuntu/venvs/lightup/lib/python3.8/site-packages/django/db/models/manager.py", line 85, in manager_method
    return getattr(self.get_queryset(), name)(*args, **kwargs)
  File "/home/ubuntu/venvs/lightup/lib/python3.8/site-packages/django/db/models/query.py", line 447, in create
    obj.save(force_insert=True, using=self.db)
  File "/home/ubuntu/venvs/lightup/lib/python3.8/site-packages/django/contrib/auth/base_user.py", line 67, in save
    super().save(*args, **kwargs)
  File "/home/ubuntu/venvs/lightup/lib/python3.8/site-packages/django/db/models/base.py", line 753, in save
    self.save_base(using=using, force_insert=force_insert,
  File "/home/ubuntu/venvs/lightup/lib/python3.8/site-packages/django/db/models/base.py", line 790, in save_base
    updated = self._save_table(
  File "/home/ubuntu/venvs/lightup/lib/python3.8/site-packages/django/db/models/base.py", line 895, in _save_table
    results = self._do_insert(cls._base_manager, using, fields, returning_fields, raw)
  File "/home/ubuntu/venvs/lightup/lib/python3.8/site-packages/django/db/models/base.py", line 933, in _do_insert
    return manager._insert(
  File "/home/ubuntu/venvs/lightup/lib/python3.8/site-packages/django/db/models/manager.py", line 85, in manager_method
    return getattr(self.get_queryset(), name)(*args, **kwargs)
  File "/home/ubuntu/venvs/lightup/lib/python3.8/site-packages/django/db/models/query.py", line 1254, in _insert
    return query.get_compiler(using=using).execute_sql(returning_fields)
  File "/home/ubuntu/venvs/lightup/lib/python3.8/site-packages/django/db/models/sql/compiler.py", line 1397, in execute_sql
    cursor.execute(sql, params)
  File "/home/ubuntu/venvs/lightup/lib/python3.8/site-packages/django/db/backends/utils.py", line 98, in execute
    return super().execute(sql, params)
  File "/home/ubuntu/venvs/lightup/lib/python3.8/site-packages/django/db/backends/utils.py", line 66, in execute
    return self._execute_with_wrappers(sql, params, many=False, executor=self._execute)
  File "/home/ubuntu/venvs/lightup/lib/python3.8/site-packages/django/db/backends/utils.py", line 75, in _execute_with_wrappers
    return executor(sql, params, many, context)
  File "/home/ubuntu/venvs/lightup/lib/python3.8/site-packages/django/db/backends/utils.py", line 84, in _execute
    return self.cursor.execute(sql, params)
  File "/home/ubuntu/venvs/lightup/lib/python3.8/site-packages/django/db/utils.py", line 90, in __exit__
    raise dj_exc_value.with_traceback(traceback) from exc_value
  File "/home/ubuntu/venvs/lightup/lib/python3.8/site-packages/django/db/backends/utils.py", line 84, in _execute
    return self.cursor.execute(sql, params)
  File "/home/ubuntu/venvs/lightup/lib/python3.8/site-packages/django/db/backends/sqlite3/base.py", line 413, in execute
    return Database.Cursor.execute(self, query, params)
django.db.utils.IntegrityError: UNIQUE constraint failed: auth_user.username
HTTP POST /users/ 500 [0.07, 221.146.36.98:58007]
HTTP GET /users/ 200 [0.06, 221.146.36.98:58015]
Unauthorized: /login/
HTTP POST /login/ 401 [0.16, 221.146.36.98:58033]
Unauthorized: /login/
HTTP POST /login/ 401 [0.16, 221.146.36.98:58033]
Method Not Allowed: /login/
HTTP GET /login/ 405 [0.02, 221.146.36.98:58078]
Not Found: /favicon.ico
HTTP GET /favicon.ico 404 [0.01, 221.146.36.98:58079]
Unauthorized: /login/
HTTP POST /login/ 401 [0.17, 221.146.36.98:58078]
Unauthorized: /login/
HTTP POST /login/ 401 [0.16, 221.146.36.98:58117]
Unauthorized: /login/
HTTP POST /login/ 401 [0.16, 221.146.36.98:58117]
HTTP GET / 200 [0.01, 45.61.146.242:47690]
<class 'lightup.models.UserInfo'>
<class 'lightup.models.UserLocation'>
<class 'lightup.models.Donation'>
<class 'lightup.models.DonationUser'>
<class 'lightup.models.BorrowState'>
Watching for file changes with StatReloader
HTTP GET / 200 [0.04, 112.148.239.218:64953]
HTTP GET / 200 [0.01, 112.148.239.218:64953]
HTTP GET /users/ 200 [0.09, 211.49.7.207:57483]
Bad Request: /users/
HTTP POST /users/ 400 [0.02, 211.49.7.207:57533]
HTTP POST /users/ 201 [0.20, 211.49.7.207:57533]
Unauthorized: /login/
HTTP POST /login/ 401 [0.16, 211.49.7.207:57533]
Unauthorized: /login/
HTTP POST /login/ 401 [0.16, 211.49.7.207:57533]
HTTP POST /login/ 200 [0.18, 211.49.7.207:57533]
Unauthorized: /login/
HTTP POST /login/ 401 [0.16, 211.49.7.207:57766]
Unauthorized: /login/
HTTP POST /login/ 401 [0.16, 211.49.7.207:57766]
HTTP POST /login/ 200 [0.16, 211.49.7.207:57766]
HTTP GET /donation/ 200 [0.03, 211.49.7.207:58274]
Not Found: /favicon.ico
HTTP GET /favicon.ico 404 [0.01, 211.49.7.207:58275]
HTTP GET / 200 [0.01, 112.148.239.218:54133]
HTTP GET /static/rest_framework/css/bootstrap.min.css 200 [0.00, 112.148.239.218:54133]
HTTP GET /static/rest_framework/css/bootstrap-tweaks.css 200 [0.01, 112.148.239.218:61173]
HTTP GET /static/rest_framework/css/prettify.css 200 [0.00, 112.148.239.218:53519]
HTTP GET /static/rest_framework/css/default.css 200 [0.01, 112.148.239.218:51061]
HTTP GET /static/rest_framework/js/jquery-3.5.1.min.js 200 [0.01, 112.148.239.218:53684]
HTTP GET /static/rest_framework/js/ajax-form.js 200 [0.01, 112.148.239.218:62921]
HTTP GET /static/rest_framework/js/csrf.js 200 [0.00, 112.148.239.218:61173]
HTTP GET /static/rest_framework/js/bootstrap.min.js 200 [0.01, 112.148.239.218:53519]
HTTP GET /static/rest_framework/js/prettify-min.js 200 [0.01, 112.148.239.218:51061]
HTTP GET /static/rest_framework/js/default.js 200 [0.00, 112.148.239.218:54133]
HTTP GET /static/rest_framework/img/grid.png 200 [0.00, 112.148.239.218:61173]
Not Found: /favicon.ico
HTTP GET /favicon.ico 404 [0.01, 112.148.239.218:61173]
HTTP GET /donation_user/ 200 [0.03, 112.148.239.218:61173]
HTTP GET / 200 [0.01, 112.148.239.218:61173]
HTTP GET /donation/ 200 [0.03, 112.148.239.218:61173]
HTTP GET /donation/ 200 [0.03, 211.49.7.207:58879]
HTTP POST /donation/ 201 [0.03, 112.148.239.218:59601]
HTTP GET / 200 [0.01, 112.148.239.218:59601]
HTTP GET /donation/ 200 [0.03, 112.148.239.218:59601]
HTTP POST /login/ 200 [0.16, 211.49.7.207:59009]
HTTP POST /donation/ 201 [0.03, 112.148.239.218:65243]
HTTP GET / 200 [0.01, 112.148.239.218:65243]
HTTP GET /donation/ 200 [0.03, 112.148.239.218:65243]
/home/ubuntu/projects/helper/lightup_restAPI/views.py changed, reloading.
<class 'lightup.models.UserInfo'>
<class 'lightup.models.UserLocation'>
<class 'lightup.models.Donation'>
<class 'lightup.models.DonationUser'>
<class 'lightup.models.BorrowState'>
Performing system checks...

System check identified no issues (0 silenced).
August 14, 2021 - 18:11:09
Django version 3.1.3, using settings 'lightup_project.settings'
Starting ASGI/Channels version 3.0.4 development server at http://0:8000/
Quit the server with CONTROL-C.
Watching for file changes with StatReloader
Exception in thread django-main-thread:
Traceback (most recent call last):
  File "/usr/lib/python3.8/threading.py", line 932, in _bootstrap_inner
    self.run()
  File "/usr/lib/python3.8/threading.py", line 870, in run
    self._target(*self._args, **self._kwargs)
  File "/home/ubuntu/venvs/lightup/lib/python3.8/site-packages/django/utils/autoreload.py", line 53, in wrapper
    fn(*args, **kwargs)
  File "/home/ubuntu/venvs/lightup/lib/python3.8/site-packages/channels/management/commands/runserver.py", line 75, in inner_run
    self.check(display_num_errors=True)
  File "/home/ubuntu/venvs/lightup/lib/python3.8/site-packages/django/core/management/base.py", line 392, in check
    all_issues = checks.run_checks(
  File "/home/ubuntu/venvs/lightup/lib/python3.8/site-packages/django/core/checks/registry.py", line 70, in run_checks
    new_errors = check(app_configs=app_configs, databases=databases)
  File "/home/ubuntu/venvs/lightup/lib/python3.8/site-packages/django/core/checks/urls.py", line 13, in check_url_config
    return check_resolver(resolver)
  File "/home/ubuntu/venvs/lightup/lib/python3.8/site-packages/django/core/checks/urls.py", line 23, in check_resolver
    return check_method()
  File "/home/ubuntu/venvs/lightup/lib/python3.8/site-packages/django/urls/resolvers.py", line 408, in check
    for pattern in self.url_patterns:
  File "/home/ubuntu/venvs/lightup/lib/python3.8/site-packages/django/utils/functional.py", line 48, in __get__
    res = instance.__dict__[self.name] = self.func(instance)
  File "/home/ubuntu/venvs/lightup/lib/python3.8/site-packages/django/urls/resolvers.py", line 589, in url_patterns
    patterns = getattr(self.urlconf_module, "urlpatterns", self.urlconf_module)
  File "/home/ubuntu/venvs/lightup/lib/python3.8/site-packages/django/utils/functional.py", line 48, in __get__
    res = instance.__dict__[self.name] = self.func(instance)
  File "/home/ubuntu/venvs/lightup/lib/python3.8/site-packages/django/urls/resolvers.py", line 582, in urlconf_module
    return import_module(self.urlconf_name)
  File "/usr/lib/python3.8/importlib/__init__.py", line 127, in import_module
    return _bootstrap._gcd_import(name[level:], package, level)
  File "<frozen importlib._bootstrap>", line 1014, in _gcd_import
  File "<frozen importlib._bootstrap>", line 991, in _find_and_load
  File "<frozen importlib._bootstrap>", line 975, in _find_and_load_unlocked
  File "<frozen importlib._bootstrap>", line 671, in _load_unlocked
  File "<frozen importlib._bootstrap_external>", line 848, in exec_module
  File "<frozen importlib._bootstrap>", line 219, in _call_with_frames_removed
  File "/home/ubuntu/projects/helper/lightup_project/urls.py", line 20, in <module>
    from lightup_restAPI import views
  File "/home/ubuntu/projects/helper/lightup_restAPI/views.py", line 12, in <module>
    from haversine import haversine
ModuleNotFoundError: No module named 'haversine'
Watching for file changes with StatReloader
HTTP GET / 200 [0.06, 112.148.239.218:63444]
